<?xml version="1.0" ?>
<robot xmlns:xacro="http://ros.org/wiki/xacro">
  <xacro:macro name="torso" params="prefix">

	<!-- link list -->
  <link
    name="base_link">
    <inertial>
      <origin
        xyz="-0.11144 -4.9089E-05 0.10433"
        rpy="0 0 0" />
      <mass
        value="28.727" />
      <inertia
        ixx="0.3449"
        ixy="-0.00060471"
        ixz="-0.0072714"
        iyy="0.73969"
        iyz="5.6352E-05"
        izz="0.82224" />
    </inertial>
    <visual>
      <origin
        xyz="0 0 0"
        rpy="0 0 0" />
      <geometry>
        <mesh
          filename="package://motoman_sda20d_support/meshes/visual/base_link.STL" />
      </geometry>
      <material
        name="">
        <color
          rgba="0.79216 0.81961 0.93333 1" />
      </material>
    </visual>
    <collision>
      <origin
        xyz="0 0 0"
        rpy="0 0 0" />
      <geometry>
        <mesh
          filename="package://motoman_sda20d_support/meshes/collision/base_link.STL" />
      </geometry>
    </collision>
  </link>

  <link
    name="${prefix}link_b1">
    <inertial>
      <origin
        xyz="0.026706 1.1222E-05 0.19713"
        rpy="0 0 0" />
      <mass
        value="36.439" />
      <inertia
        ixx="0.62924"
        ixy="7.5604E-05"
        ixz="-0.065715"
        iyy="0.97273"
        iyz="7.3187E-05"
        izz="0.67513" />
    </inertial>
    <visual>
      <origin
        xyz="0 0 0"
        rpy="0 0 0" />
      <geometry>
        <mesh
          filename="package://motoman_sda20d_support/meshes/visual/link_b1.STL" />
      </geometry>
      <material
        name="">
        <color
          rgba="0.79216 0.81961 0.93333 1" />
      </material>
    </visual>
    <collision>
      <origin
        xyz="0 0 0"
        rpy="0 0 0" />
      <geometry>
        <mesh
          filename="package://motoman_sda20d_support/meshes/collision/link_b1.STL" />
      </geometry>
    </collision>
  </link>

	<!-- joint list -->

  <joint
    name="${prefix}joint_b1"
    type="revolute">
    <origin
      xyz="0 0 0.2516"
      rpy="0 0 0" />
    <parent
      link="base_link" />
    <child
      link="${prefix}link_b1" />
    <axis
      xyz="0 0 1" />
    <limit
      effort="0"
      lower="-1.5555423498153687"
      upper="1.5555423498153687"
      velocity="2.181816" />
  </joint>

	<!-- end of joint list -->

</xacro:macro>
</robot>
